2020-10-08 19:29:57,786 ERROR: Exception on / [GET] [in /home/shazib/microblog/venv/lib/python3.8/site-packages/flask/app.py:1891]
Traceback (most recent call last):
  File "/home/shazib/microblog/venv/lib/python3.8/site-packages/flask/app.py", line 2447, in wsgi_app
    response = self.full_dispatch_request()
  File "/home/shazib/microblog/venv/lib/python3.8/site-packages/flask/app.py", line 1952, in full_dispatch_request
    rv = self.handle_user_exception(e)
  File "/home/shazib/microblog/venv/lib/python3.8/site-packages/flask/app.py", line 1821, in handle_user_exception
    reraise(exc_type, exc_value, tb)
  File "/home/shazib/microblog/venv/lib/python3.8/site-packages/flask/_compat.py", line 39, in reraise
    raise value
  File "/home/shazib/microblog/venv/lib/python3.8/site-packages/flask/app.py", line 1950, in full_dispatch_request
    rv = self.dispatch_request()
  File "/home/shazib/microblog/venv/lib/python3.8/site-packages/flask/app.py", line 1936, in dispatch_request
    return self.view_functions[rule.endpoint](**req.view_args)
  File "/home/shazib/microblog/venv/lib/python3.8/site-packages/flask_login/utils.py", line 272, in decorated_view
    return func(*args, **kwargs)
  File "/home/shazib/microblog/app/routes.py", line 27, in index
    return render_template('index.html', title='Home',form=form,
  File "/home/shazib/microblog/venv/lib/python3.8/site-packages/flask/templating.py", line 137, in render_template
    return _render(
  File "/home/shazib/microblog/venv/lib/python3.8/site-packages/flask/templating.py", line 120, in _render
    rv = template.render(context)
  File "/home/shazib/microblog/venv/lib/python3.8/site-packages/jinja2/environment.py", line 1090, in render
    self.environment.handle_exception()
  File "/home/shazib/microblog/venv/lib/python3.8/site-packages/jinja2/environment.py", line 832, in handle_exception
    reraise(*rewrite_traceback_stack(source=source))
  File "/home/shazib/microblog/venv/lib/python3.8/site-packages/jinja2/_compat.py", line 28, in reraise
    raise value.with_traceback(tb)
  File "/home/shazib/microblog/app/templates/index.html", line 1, in top-level template code
    {% extends "base.html"%}
  File "/home/shazib/microblog/app/templates/base.html", line 30, in top-level template code
    {% block content %}{% endblock %}
  File "/home/shazib/microblog/app/templates/index.html", line 25, in block "content"
    <a href="{{url_for('next_url')}}">Older posts</a>
  File "/home/shazib/microblog/venv/lib/python3.8/site-packages/flask/helpers.py", line 370, in url_for
    return appctx.app.handle_url_build_error(error, endpoint, values)
  File "/home/shazib/microblog/venv/lib/python3.8/site-packages/flask/app.py", line 2216, in handle_url_build_error
    reraise(exc_type, exc_value, tb)
  File "/home/shazib/microblog/venv/lib/python3.8/site-packages/flask/_compat.py", line 39, in reraise
    raise value
  File "/home/shazib/microblog/venv/lib/python3.8/site-packages/flask/helpers.py", line 357, in url_for
    rv = url_adapter.build(
  File "/home/shazib/microblog/venv/lib/python3.8/site-packages/werkzeug/routing.py", line 2179, in build
    raise BuildError(endpoint, values, method, self)
werkzeug.routing.BuildError: Could not build url for endpoint 'next_url'. Did you mean 'edit_profile' instead?
2020-10-08 19:30:31,422 INFO: Microblog startup [in /home/shazib/microblog/app/__init__.py:45]
2020-10-08 19:30:46,161 ERROR: Exception on /explore [GET] [in /home/shazib/microblog/venv/lib/python3.8/site-packages/flask/app.py:1891]
Traceback (most recent call last):
  File "/home/shazib/microblog/venv/lib/python3.8/site-packages/flask/app.py", line 2447, in wsgi_app
    response = self.full_dispatch_request()
  File "/home/shazib/microblog/venv/lib/python3.8/site-packages/flask/app.py", line 1952, in full_dispatch_request
    rv = self.handle_user_exception(e)
  File "/home/shazib/microblog/venv/lib/python3.8/site-packages/flask/app.py", line 1821, in handle_user_exception
    reraise(exc_type, exc_value, tb)
  File "/home/shazib/microblog/venv/lib/python3.8/site-packages/flask/_compat.py", line 39, in reraise
    raise value
  File "/home/shazib/microblog/venv/lib/python3.8/site-packages/flask/app.py", line 1950, in full_dispatch_request
    rv = self.dispatch_request()
  File "/home/shazib/microblog/venv/lib/python3.8/site-packages/flask/app.py", line 1936, in dispatch_request
    return self.view_functions[rule.endpoint](**req.view_args)
  File "/home/shazib/microblog/venv/lib/python3.8/site-packages/flask_login/utils.py", line 272, in decorated_view
    return func(*args, **kwargs)
  File "/home/shazib/microblog/app/routes.py", line 146, in explore
    if posts.prev_next else None
AttributeError: 'Pagination' object has no attribute 'prev_next'
2020-10-08 19:32:41,081 INFO: Microblog startup [in /home/shazib/microblog/app/__init__.py:45]
2020-10-08 19:33:04,280 ERROR: Exception on /explore [GET] [in /home/shazib/microblog/venv/lib/python3.8/site-packages/flask/app.py:1891]
Traceback (most recent call last):
  File "/home/shazib/microblog/venv/lib/python3.8/site-packages/flask/app.py", line 2447, in wsgi_app
    response = self.full_dispatch_request()
  File "/home/shazib/microblog/venv/lib/python3.8/site-packages/flask/app.py", line 1952, in full_dispatch_request
    rv = self.handle_user_exception(e)
  File "/home/shazib/microblog/venv/lib/python3.8/site-packages/flask/app.py", line 1821, in handle_user_exception
    reraise(exc_type, exc_value, tb)
  File "/home/shazib/microblog/venv/lib/python3.8/site-packages/flask/_compat.py", line 39, in reraise
    raise value
  File "/home/shazib/microblog/venv/lib/python3.8/site-packages/flask/app.py", line 1950, in full_dispatch_request
    rv = self.dispatch_request()
  File "/home/shazib/microblog/venv/lib/python3.8/site-packages/flask/app.py", line 1936, in dispatch_request
    return self.view_functions[rule.endpoint](**req.view_args)
  File "/home/shazib/microblog/venv/lib/python3.8/site-packages/flask_login/utils.py", line 272, in decorated_view
    return func(*args, **kwargs)
  File "/home/shazib/microblog/app/routes.py", line 146, in explore
    if posts.prev_next else None
AttributeError: 'Pagination' object has no attribute 'prev_next'
2020-10-08 19:38:37,226 INFO: Microblog startup [in /home/shazib/microblog/app/__init__.py:45]
2020-10-08 19:54:24,965 INFO: Microblog startup [in /home/shazib/microblog/app/__init__.py:45]
2020-10-08 19:54:29,230 ERROR: Exception on /user/Haris [GET] [in /home/shazib/microblog/venv/lib/python3.8/site-packages/flask/app.py:1891]
Traceback (most recent call last):
  File "/home/shazib/microblog/venv/lib/python3.8/site-packages/flask/app.py", line 2447, in wsgi_app
    response = self.full_dispatch_request()
  File "/home/shazib/microblog/venv/lib/python3.8/site-packages/flask/app.py", line 1952, in full_dispatch_request
    rv = self.handle_user_exception(e)
  File "/home/shazib/microblog/venv/lib/python3.8/site-packages/flask/app.py", line 1821, in handle_user_exception
    reraise(exc_type, exc_value, tb)
  File "/home/shazib/microblog/venv/lib/python3.8/site-packages/flask/_compat.py", line 39, in reraise
    raise value
  File "/home/shazib/microblog/venv/lib/python3.8/site-packages/flask/app.py", line 1950, in full_dispatch_request
    rv = self.dispatch_request()
  File "/home/shazib/microblog/venv/lib/python3.8/site-packages/flask/app.py", line 1936, in dispatch_request
    return self.view_functions[rule.endpoint](**req.view_args)
  File "/home/shazib/microblog/venv/lib/python3.8/site-packages/flask_login/utils.py", line 272, in decorated_view
    return func(*args, **kwargs)
  File "/home/shazib/microblog/app/routes.py", line 72, in user
    page, app.config[POST_PER_PAGE], False)
NameError: name 'POST_PER_PAGE' is not defined
2020-10-08 19:55:13,902 INFO: Microblog startup [in /home/shazib/microblog/app/__init__.py:45]
2020-10-08 20:25:22,149 INFO: Microblog startup [in /home/shazib/microblog/app/__init__.py:45]
2020-10-08 20:32:49,542 INFO: Microblog startup [in /home/shazib/microblog/app/__init__.py:45]
2020-10-09 00:02:22,511 INFO: Microblog startup [in /home/shazib/microblog/app/__init__.py:47]
2020-10-09 00:15:38,568 INFO: Microblog startup [in /home/shazib/microblog/app/__init__.py:47]
2020-10-09 15:29:09,772 INFO: Microblog startup [in /home/shazib/microblog/app/__init__.py:47]
2020-10-09 21:40:38,655 INFO: Microblog startup [in /home/shazib/microblog/app/__init__.py:47]
2020-10-10 20:17:22,615 INFO: Microblog startup [in /home/shazib/microblog/app/__init__.py:47]
2020-10-10 20:27:32,524 ERROR: Exception on /reset_password_request [GET] [in /home/shazib/microblog/venv/lib/python3.8/site-packages/flask/app.py:1891]
Traceback (most recent call last):
  File "/home/shazib/microblog/venv/lib/python3.8/site-packages/flask/app.py", line 2447, in wsgi_app
    response = self.full_dispatch_request()
  File "/home/shazib/microblog/venv/lib/python3.8/site-packages/flask/app.py", line 1952, in full_dispatch_request
    rv = self.handle_user_exception(e)
  File "/home/shazib/microblog/venv/lib/python3.8/site-packages/flask/app.py", line 1821, in handle_user_exception
    reraise(exc_type, exc_value, tb)
  File "/home/shazib/microblog/venv/lib/python3.8/site-packages/flask/_compat.py", line 39, in reraise
    raise value
  File "/home/shazib/microblog/venv/lib/python3.8/site-packages/flask/app.py", line 1950, in full_dispatch_request
    rv = self.dispatch_request()
  File "/home/shazib/microblog/venv/lib/python3.8/site-packages/flask/app.py", line 1936, in dispatch_request
    return self.view_functions[rule.endpoint](**req.view_args)
  File "/home/shazib/microblog/app/routes.py", line 158, in reset_password_request
    form= ResetPasswordRequestForm()
NameError: name 'ResetPasswordRequestForm' is not defined
2020-10-10 20:39:41,335 INFO: Microblog startup [in /home/shazib/microblog/app/__init__.py:47]
