2020-10-07 17:41:49,455 ERROR: Exception on /index [GET] [in /home/shazib/microblog/venv/lib/python3.8/site-packages/flask/app.py:1891]
Traceback (most recent call last):
  File "/home/shazib/microblog/venv/lib/python3.8/site-packages/flask/app.py", line 2447, in wsgi_app
    response = self.full_dispatch_request()
  File "/home/shazib/microblog/venv/lib/python3.8/site-packages/flask/app.py", line 1952, in full_dispatch_request
    rv = self.handle_user_exception(e)
  File "/home/shazib/microblog/venv/lib/python3.8/site-packages/flask/app.py", line 1821, in handle_user_exception
    reraise(exc_type, exc_value, tb)
  File "/home/shazib/microblog/venv/lib/python3.8/site-packages/flask/_compat.py", line 39, in reraise
    raise value
  File "/home/shazib/microblog/venv/lib/python3.8/site-packages/flask/app.py", line 1950, in full_dispatch_request
    rv = self.dispatch_request()
  File "/home/shazib/microblog/venv/lib/python3.8/site-packages/flask/app.py", line 1936, in dispatch_request
    return self.view_functions[rule.endpoint](**req.view_args)
  File "/home/shazib/microblog/venv/lib/python3.8/site-packages/flask_login/utils.py", line 272, in decorated_view
    return func(*args, **kwargs)
  File "/home/shazib/microblog/app/routes.py", line 20, in index
    posts = current_user.followed_posts().all()
  File "/home/shazib/microblog/app/models.py", line 57, in followed_posts
    return followed.union(own).order_by(Post.timestamp.desc())
NameError: name 'followed' is not defined
2020-10-07 17:42:37,880 ERROR: Exception on /index [GET] [in /home/shazib/microblog/venv/lib/python3.8/site-packages/flask/app.py:1891]
Traceback (most recent call last):
  File "/home/shazib/microblog/venv/lib/python3.8/site-packages/flask/app.py", line 2447, in wsgi_app
    response = self.full_dispatch_request()
  File "/home/shazib/microblog/venv/lib/python3.8/site-packages/flask/app.py", line 1952, in full_dispatch_request
    rv = self.handle_user_exception(e)
  File "/home/shazib/microblog/venv/lib/python3.8/site-packages/flask/app.py", line 1821, in handle_user_exception
    reraise(exc_type, exc_value, tb)
  File "/home/shazib/microblog/venv/lib/python3.8/site-packages/flask/_compat.py", line 39, in reraise
    raise value
  File "/home/shazib/microblog/venv/lib/python3.8/site-packages/flask/app.py", line 1950, in full_dispatch_request
    rv = self.dispatch_request()
  File "/home/shazib/microblog/venv/lib/python3.8/site-packages/flask/app.py", line 1936, in dispatch_request
    return self.view_functions[rule.endpoint](**req.view_args)
  File "/home/shazib/microblog/venv/lib/python3.8/site-packages/flask_login/utils.py", line 272, in decorated_view
    return func(*args, **kwargs)
  File "/home/shazib/microblog/app/routes.py", line 20, in index
    posts = current_user.followed_posts().all()
  File "/home/shazib/microblog/app/models.py", line 57, in followed_posts
    return followed.union(own).order_by(Post.timestamp.desc())
NameError: name 'followed' is not defined
2020-10-07 17:44:07,319 ERROR: Exception on /index [GET] [in /home/shazib/microblog/venv/lib/python3.8/site-packages/flask/app.py:1891]
Traceback (most recent call last):
  File "/home/shazib/microblog/venv/lib/python3.8/site-packages/flask/app.py", line 2447, in wsgi_app
    response = self.full_dispatch_request()
  File "/home/shazib/microblog/venv/lib/python3.8/site-packages/flask/app.py", line 1952, in full_dispatch_request
    rv = self.handle_user_exception(e)
  File "/home/shazib/microblog/venv/lib/python3.8/site-packages/flask/app.py", line 1821, in handle_user_exception
    reraise(exc_type, exc_value, tb)
  File "/home/shazib/microblog/venv/lib/python3.8/site-packages/flask/_compat.py", line 39, in reraise
    raise value
  File "/home/shazib/microblog/venv/lib/python3.8/site-packages/flask/app.py", line 1950, in full_dispatch_request
    rv = self.dispatch_request()
  File "/home/shazib/microblog/venv/lib/python3.8/site-packages/flask/app.py", line 1936, in dispatch_request
    return self.view_functions[rule.endpoint](**req.view_args)
  File "/home/shazib/microblog/venv/lib/python3.8/site-packages/flask_login/utils.py", line 272, in decorated_view
    return func(*args, **kwargs)
  File "/home/shazib/microblog/app/routes.py", line 20, in index
    posts = current_user.followed_posts().all()
  File "/home/shazib/microblog/app/models.py", line 57, in followed_posts
    return followed.union(own).order_by(Post.timestamp.desc())
NameError: name 'followed' is not defined
2020-10-07 18:26:52,376 INFO: Microblog startup [in /home/shazib/microblog/app/__init__.py:45]
2020-10-07 18:29:17,591 INFO: Microblog startup [in /home/shazib/microblog/app/__init__.py:45]
2020-10-08 01:49:53,109 INFO: Microblog startup [in /home/shazib/microblog/app/__init__.py:45]
2020-10-08 15:32:44,774 INFO: Microblog startup [in /home/shazib/microblog/app/__init__.py:45]
2020-10-08 17:36:18,916 INFO: Microblog startup [in /home/shazib/microblog/app/__init__.py:45]
2020-10-08 17:36:27,828 ERROR: Exception on /explore [GET] [in /home/shazib/microblog/venv/lib/python3.8/site-packages/flask/app.py:1891]
Traceback (most recent call last):
  File "/home/shazib/microblog/venv/lib/python3.8/site-packages/flask/app.py", line 2447, in wsgi_app
    response = self.full_dispatch_request()
  File "/home/shazib/microblog/venv/lib/python3.8/site-packages/flask/app.py", line 1952, in full_dispatch_request
    rv = self.handle_user_exception(e)
  File "/home/shazib/microblog/venv/lib/python3.8/site-packages/flask/app.py", line 1821, in handle_user_exception
    reraise(exc_type, exc_value, tb)
  File "/home/shazib/microblog/venv/lib/python3.8/site-packages/flask/_compat.py", line 39, in reraise
    raise value
  File "/home/shazib/microblog/venv/lib/python3.8/site-packages/flask/app.py", line 1950, in full_dispatch_request
    rv = self.dispatch_request()
  File "/home/shazib/microblog/venv/lib/python3.8/site-packages/flask/app.py", line 1936, in dispatch_request
    return self.view_functions[rule.endpoint](**req.view_args)
  File "/home/shazib/microblog/venv/lib/python3.8/site-packages/flask_login/utils.py", line 272, in decorated_view
    return func(*args, **kwargs)
  File "/home/shazib/microblog/app/routes.py", line 136, in explore
    page, app.confg['POST_PER_PAGE'], False)
AttributeError: 'Flask' object has no attribute 'confg'
2020-10-08 17:36:38,284 ERROR: Exception on /explore [GET] [in /home/shazib/microblog/venv/lib/python3.8/site-packages/flask/app.py:1891]
Traceback (most recent call last):
  File "/home/shazib/microblog/venv/lib/python3.8/site-packages/flask/app.py", line 2447, in wsgi_app
    response = self.full_dispatch_request()
  File "/home/shazib/microblog/venv/lib/python3.8/site-packages/flask/app.py", line 1952, in full_dispatch_request
    rv = self.handle_user_exception(e)
  File "/home/shazib/microblog/venv/lib/python3.8/site-packages/flask/app.py", line 1821, in handle_user_exception
    reraise(exc_type, exc_value, tb)
  File "/home/shazib/microblog/venv/lib/python3.8/site-packages/flask/_compat.py", line 39, in reraise
    raise value
  File "/home/shazib/microblog/venv/lib/python3.8/site-packages/flask/app.py", line 1950, in full_dispatch_request
    rv = self.dispatch_request()
  File "/home/shazib/microblog/venv/lib/python3.8/site-packages/flask/app.py", line 1936, in dispatch_request
    return self.view_functions[rule.endpoint](**req.view_args)
  File "/home/shazib/microblog/venv/lib/python3.8/site-packages/flask_login/utils.py", line 272, in decorated_view
    return func(*args, **kwargs)
  File "/home/shazib/microblog/app/routes.py", line 136, in explore
    page, app.confg['POST_PER_PAGE'], False)
AttributeError: 'Flask' object has no attribute 'confg'
2020-10-08 17:37:24,597 INFO: Microblog startup [in /home/shazib/microblog/app/__init__.py:45]
2020-10-08 19:25:22,524 INFO: Microblog startup [in /home/shazib/microblog/app/__init__.py:45]
