2020-10-24 16:11:35,930 ERROR: Exception on /favicon.ico [GET] [in /home/shazib/microblog/venv/lib/python3.8/site-packages/flask/app.py:1891]
Traceback (most recent call last):
  File "/home/shazib/microblog/venv/lib/python3.8/site-packages/flask/app.py", line 2447, in wsgi_app
    response = self.full_dispatch_request()
  File "/home/shazib/microblog/venv/lib/python3.8/site-packages/flask/app.py", line 1952, in full_dispatch_request
    rv = self.handle_user_exception(e)
  File "/home/shazib/microblog/venv/lib/python3.8/site-packages/flask/app.py", line 1821, in handle_user_exception
    reraise(exc_type, exc_value, tb)
  File "/home/shazib/microblog/venv/lib/python3.8/site-packages/flask/_compat.py", line 39, in reraise
    raise value
  File "/home/shazib/microblog/venv/lib/python3.8/site-packages/flask/app.py", line 1948, in full_dispatch_request
    rv = self.preprocess_request()
  File "/home/shazib/microblog/venv/lib/python3.8/site-packages/flask/app.py", line 2242, in preprocess_request
    rv = func()
  File "/home/shazib/microblog/app/routes.py", line 16, in before_request
    g.locale = str(get_locale())
  File "/home/shazib/microblog/venv/lib/python3.8/site-packages/flask_babel/__init__.py", line 226, in get_locale
    rv = babel.locale_selector_func()
  File "/home/shazib/microblog/app/__init__.py", line 58, in get_locale
    return request.accept_language.best_match(app.config['LANGUAGES'])
  File "/home/shazib/microblog/venv/lib/python3.8/site-packages/werkzeug/local.py", line 347, in __getattr__
    return getattr(self._get_current_object(), name)
AttributeError: 'Request' object has no attribute 'accept_language'
2020-10-24 16:11:50,417 ERROR: Exception on /index [GET] [in /home/shazib/microblog/venv/lib/python3.8/site-packages/flask/app.py:1891]
Traceback (most recent call last):
  File "/home/shazib/microblog/venv/lib/python3.8/site-packages/flask/app.py", line 2447, in wsgi_app
    response = self.full_dispatch_request()
  File "/home/shazib/microblog/venv/lib/python3.8/site-packages/flask/app.py", line 1952, in full_dispatch_request
    rv = self.handle_user_exception(e)
  File "/home/shazib/microblog/venv/lib/python3.8/site-packages/flask/app.py", line 1821, in handle_user_exception
    reraise(exc_type, exc_value, tb)
  File "/home/shazib/microblog/venv/lib/python3.8/site-packages/flask/_compat.py", line 39, in reraise
    raise value
  File "/home/shazib/microblog/venv/lib/python3.8/site-packages/flask/app.py", line 1948, in full_dispatch_request
    rv = self.preprocess_request()
  File "/home/shazib/microblog/venv/lib/python3.8/site-packages/flask/app.py", line 2242, in preprocess_request
    rv = func()
  File "/home/shazib/microblog/app/routes.py", line 16, in before_request
    g.locale = str(get_locale())
  File "/home/shazib/microblog/venv/lib/python3.8/site-packages/flask_babel/__init__.py", line 226, in get_locale
    rv = babel.locale_selector_func()
  File "/home/shazib/microblog/app/__init__.py", line 58, in get_locale
    return request.accept_language.best_match(app.config['LANGUAGES'])
  File "/home/shazib/microblog/venv/lib/python3.8/site-packages/werkzeug/local.py", line 347, in __getattr__
    return getattr(self._get_current_object(), name)
AttributeError: 'Request' object has no attribute 'accept_language'
2020-10-24 16:11:50,751 ERROR: Exception on /favicon.ico [GET] [in /home/shazib/microblog/venv/lib/python3.8/site-packages/flask/app.py:1891]
Traceback (most recent call last):
  File "/home/shazib/microblog/venv/lib/python3.8/site-packages/flask/app.py", line 2447, in wsgi_app
    response = self.full_dispatch_request()
  File "/home/shazib/microblog/venv/lib/python3.8/site-packages/flask/app.py", line 1952, in full_dispatch_request
    rv = self.handle_user_exception(e)
  File "/home/shazib/microblog/venv/lib/python3.8/site-packages/flask/app.py", line 1821, in handle_user_exception
    reraise(exc_type, exc_value, tb)
  File "/home/shazib/microblog/venv/lib/python3.8/site-packages/flask/_compat.py", line 39, in reraise
    raise value
  File "/home/shazib/microblog/venv/lib/python3.8/site-packages/flask/app.py", line 1948, in full_dispatch_request
    rv = self.preprocess_request()
  File "/home/shazib/microblog/venv/lib/python3.8/site-packages/flask/app.py", line 2242, in preprocess_request
    rv = func()
  File "/home/shazib/microblog/app/routes.py", line 16, in before_request
    g.locale = str(get_locale())
  File "/home/shazib/microblog/venv/lib/python3.8/site-packages/flask_babel/__init__.py", line 226, in get_locale
    rv = babel.locale_selector_func()
  File "/home/shazib/microblog/app/__init__.py", line 58, in get_locale
    return request.accept_language.best_match(app.config['LANGUAGES'])
  File "/home/shazib/microblog/venv/lib/python3.8/site-packages/werkzeug/local.py", line 347, in __getattr__
    return getattr(self._get_current_object(), name)
AttributeError: 'Request' object has no attribute 'accept_language'
2020-10-24 16:18:43,206 INFO: Microblog startup [in /home/shazib/microblog/app/__init__.py:54]
2020-10-24 16:20:38,020 INFO: Microblog startup [in /home/shazib/microblog/app/__init__.py:54]
2020-10-24 18:04:17,455 INFO: Microblog startup [in /home/shazib/microblog/app/__init__.py:54]
2020-10-24 18:05:45,682 INFO: Microblog startup [in /home/shazib/microblog/app/__init__.py:54]
2020-10-25 17:56:50,129 INFO: Microblog startup [in /home/shazib/microblog/app/__init__.py:54]
2020-10-25 17:57:30,869 INFO: Microblog startup [in /home/shazib/microblog/app/__init__.py:54]
2020-10-25 17:57:45,903 INFO: Microblog startup [in /home/shazib/microblog/app/__init__.py:54]
2020-10-25 17:59:18,784 INFO: Microblog startup [in /home/shazib/microblog/app/__init__.py:54]
2020-10-25 18:03:51,984 INFO: Microblog startup [in /home/shazib/microblog/app/__init__.py:54]
2020-10-25 18:05:08,474 INFO: Microblog startup [in /home/shazib/microblog/app/__init__.py:54]
2020-10-25 18:05:20,633 INFO: Microblog startup [in /home/shazib/microblog/app/__init__.py:54]
2020-10-25 18:05:24,452 INFO: Microblog startup [in /home/shazib/microblog/app/__init__.py:54]
2020-10-25 18:05:27,766 INFO: Microblog startup [in /home/shazib/microblog/app/__init__.py:54]
2020-10-25 18:07:03,699 INFO: Microblog startup [in /home/shazib/microblog/app/__init__.py:54]
2020-10-25 18:07:08,504 INFO: Microblog startup [in /home/shazib/microblog/app/__init__.py:54]
2020-10-25 18:07:23,070 INFO: Microblog startup [in /home/shazib/microblog/app/__init__.py:54]
2020-10-25 18:07:41,474 INFO: Microblog startup [in /home/shazib/microblog/app/__init__.py:54]
2020-10-25 18:14:07,587 INFO: Microblog startup [in /home/shazib/microblog/app/__init__.py:54]
2020-10-27 00:32:45,020 INFO: Microblog startup [in /home/shazib/microblog/app/__init__.py:56]
2020-10-27 00:34:33,867 INFO: Microblog startup [in /home/shazib/microblog/app/__init__.py:56]
2020-10-27 00:37:46,719 INFO: Microblog startup [in /home/shazib/microblog/app/__init__.py:56]
2020-10-28 21:16:57,214 INFO: Microblog startup [in /home/shazib/microblog/app/__init__.py:56]
2020-10-28 21:23:38,691 INFO: Microblog startup [in /home/shazib/microblog/app/__init__.py:56]
2020-11-03 20:13:02,893 INFO: Microblog startup [in /home/shazib/microblog/app/__init__.py:56]
2020-11-04 14:33:29,069 INFO: Microblog startup [in /home/shazib/microblog/app/__init__.py:56]
2020-11-04 14:36:17,991 ERROR: Exception on /api/users/1 [GET] [in /home/shazib/microblog/venv/lib/python3.8/site-packages/flask/app.py:1891]
Traceback (most recent call last):
  File "/home/shazib/microblog/venv/lib/python3.8/site-packages/flask/app.py", line 2447, in wsgi_app
    response = self.full_dispatch_request()
  File "/home/shazib/microblog/venv/lib/python3.8/site-packages/flask/app.py", line 1952, in full_dispatch_request
    rv = self.handle_user_exception(e)
  File "/home/shazib/microblog/venv/lib/python3.8/site-packages/flask/app.py", line 1821, in handle_user_exception
    reraise(exc_type, exc_value, tb)
  File "/home/shazib/microblog/venv/lib/python3.8/site-packages/flask/_compat.py", line 39, in reraise
    raise value
  File "/home/shazib/microblog/venv/lib/python3.8/site-packages/flask/app.py", line 1950, in full_dispatch_request
    rv = self.dispatch_request()
  File "/home/shazib/microblog/venv/lib/python3.8/site-packages/flask/app.py", line 1936, in dispatch_request
    return self.view_functions[rule.endpoint](**req.view_args)
  File "/home/shazib/microblog/app/api/users.py", line 7, in get_user
    return jsonify(User.query.get_or_404(id).to_dict())
  File "/home/shazib/microblog/app/models.py", line 107, in to_dict
    'self':url_for('api.get_user', id=self.id),
NameError: name 'url_for' is not defined
2020-11-04 14:36:35,350 ERROR: Exception on /api/users/1 [GET] [in /home/shazib/microblog/venv/lib/python3.8/site-packages/flask/app.py:1891]
Traceback (most recent call last):
  File "/home/shazib/microblog/venv/lib/python3.8/site-packages/flask/app.py", line 2447, in wsgi_app
    response = self.full_dispatch_request()
  File "/home/shazib/microblog/venv/lib/python3.8/site-packages/flask/app.py", line 1952, in full_dispatch_request
    rv = self.handle_user_exception(e)
  File "/home/shazib/microblog/venv/lib/python3.8/site-packages/flask/app.py", line 1821, in handle_user_exception
    reraise(exc_type, exc_value, tb)
  File "/home/shazib/microblog/venv/lib/python3.8/site-packages/flask/_compat.py", line 39, in reraise
    raise value
  File "/home/shazib/microblog/venv/lib/python3.8/site-packages/flask/app.py", line 1950, in full_dispatch_request
    rv = self.dispatch_request()
  File "/home/shazib/microblog/venv/lib/python3.8/site-packages/flask/app.py", line 1936, in dispatch_request
    return self.view_functions[rule.endpoint](**req.view_args)
  File "/home/shazib/microblog/app/api/users.py", line 7, in get_user
    return jsonify(User.query.get_or_404(id).to_dict())
  File "/home/shazib/microblog/app/models.py", line 107, in to_dict
    'self':url_for('api.get_user', id=self.id),
NameError: name 'url_for' is not defined
