2020-10-10 20:39:48,069 ERROR: Exception on /reset_password_request [GET] [in /home/shazib/microblog/venv/lib/python3.8/site-packages/flask/app.py:1891]
Traceback (most recent call last):
  File "/home/shazib/microblog/venv/lib/python3.8/site-packages/flask/app.py", line 2447, in wsgi_app
    response = self.full_dispatch_request()
  File "/home/shazib/microblog/venv/lib/python3.8/site-packages/flask/app.py", line 1952, in full_dispatch_request
    rv = self.handle_user_exception(e)
  File "/home/shazib/microblog/venv/lib/python3.8/site-packages/flask/app.py", line 1821, in handle_user_exception
    reraise(exc_type, exc_value, tb)
  File "/home/shazib/microblog/venv/lib/python3.8/site-packages/flask/_compat.py", line 39, in reraise
    raise value
  File "/home/shazib/microblog/venv/lib/python3.8/site-packages/flask/app.py", line 1950, in full_dispatch_request
    rv = self.dispatch_request()
  File "/home/shazib/microblog/venv/lib/python3.8/site-packages/flask/app.py", line 1936, in dispatch_request
    return self.view_functions[rule.endpoint](**req.view_args)
  File "/home/shazib/microblog/app/routes.py", line 158, in reset_password_request
    form = ResetPasswordRequestForm()
  File "/home/shazib/microblog/venv/lib/python3.8/site-packages/wtforms/form.py", line 208, in __call__
    return type.__call__(cls, *args, **kwargs)
  File "/home/shazib/microblog/venv/lib/python3.8/site-packages/flask_wtf/form.py", line 87, in __init__
    super(FlaskForm, self).__init__(formdata=formdata, **kwargs)
  File "/home/shazib/microblog/venv/lib/python3.8/site-packages/wtforms/form.py", line 268, in __init__
    super(Form, self).__init__(self._unbound_fields, meta=meta_obj, prefix=prefix)
  File "/home/shazib/microblog/venv/lib/python3.8/site-packages/wtforms/form.py", line 51, in __init__
    field = meta.bind_field(self, unbound_field, options)
  File "/home/shazib/microblog/venv/lib/python3.8/site-packages/wtforms/meta.py", line 27, in bind_field
    return unbound_field.bind(form=form, **options)
  File "/home/shazib/microblog/venv/lib/python3.8/site-packages/wtforms/fields/core.py", line 376, in bind
    return self.field_class(*self.args, **kw)
TypeError: __init__() got an unexpected keyword argument 'validate'
2020-10-10 20:41:05,225 INFO: Microblog startup [in /home/shazib/microblog/app/__init__.py:47]
2020-10-10 21:43:41,440 ERROR: Exception on /reset_password_request [POST] [in /home/shazib/microblog/venv/lib/python3.8/site-packages/flask/app.py:1891]
Traceback (most recent call last):
  File "/home/shazib/microblog/venv/lib/python3.8/site-packages/flask/app.py", line 2447, in wsgi_app
    response = self.full_dispatch_request()
  File "/home/shazib/microblog/venv/lib/python3.8/site-packages/flask/app.py", line 1952, in full_dispatch_request
    rv = self.handle_user_exception(e)
  File "/home/shazib/microblog/venv/lib/python3.8/site-packages/flask/app.py", line 1821, in handle_user_exception
    reraise(exc_type, exc_value, tb)
  File "/home/shazib/microblog/venv/lib/python3.8/site-packages/flask/_compat.py", line 39, in reraise
    raise value
  File "/home/shazib/microblog/venv/lib/python3.8/site-packages/flask/app.py", line 1950, in full_dispatch_request
    rv = self.dispatch_request()
  File "/home/shazib/microblog/venv/lib/python3.8/site-packages/flask/app.py", line 1936, in dispatch_request
    return self.view_functions[rule.endpoint](**req.view_args)
  File "/home/shazib/microblog/app/routes.py", line 162, in reset_password_request
    send_password_reset_email(user)
NameError: name 'send_password_reset_email' is not defined
2020-10-10 21:46:00,500 INFO: Microblog startup [in /home/shazib/microblog/app/__init__.py:47]
2020-10-10 21:46:19,669 ERROR: Exception on /reset_password_request [POST] [in /home/shazib/microblog/venv/lib/python3.8/site-packages/flask/app.py:1891]
Traceback (most recent call last):
  File "/home/shazib/microblog/venv/lib/python3.8/site-packages/flask/app.py", line 2447, in wsgi_app
    response = self.full_dispatch_request()
  File "/home/shazib/microblog/venv/lib/python3.8/site-packages/flask/app.py", line 1952, in full_dispatch_request
    rv = self.handle_user_exception(e)
  File "/home/shazib/microblog/venv/lib/python3.8/site-packages/flask/app.py", line 1821, in handle_user_exception
    reraise(exc_type, exc_value, tb)
  File "/home/shazib/microblog/venv/lib/python3.8/site-packages/flask/_compat.py", line 39, in reraise
    raise value
  File "/home/shazib/microblog/venv/lib/python3.8/site-packages/flask/app.py", line 1950, in full_dispatch_request
    rv = self.dispatch_request()
  File "/home/shazib/microblog/venv/lib/python3.8/site-packages/flask/app.py", line 1936, in dispatch_request
    return self.view_functions[rule.endpoint](**req.view_args)
  File "/home/shazib/microblog/app/routes.py", line 162, in reset_password_request
    send_password_reset_email(user)
NameError: name 'send_password_reset_email' is not defined
2020-10-10 21:58:08,846 INFO: Microblog startup [in /home/shazib/microblog/app/__init__.py:47]
2020-10-10 22:27:38,662 INFO: Microblog startup [in /home/shazib/microblog/app/__init__.py:47]
2020-10-10 22:33:03,622 INFO: Microblog startup [in /home/shazib/microblog/app/__init__.py:47]
2020-10-10 22:42:23,270 INFO: Microblog startup [in /home/shazib/microblog/app/__init__.py:47]
2020-10-12 14:57:57,997 INFO: Microblog startup [in /home/shazib/microblog/app/__init__.py:49]
2020-10-12 15:05:12,829 INFO: Microblog startup [in /home/shazib/microblog/app/__init__.py:49]
2020-10-12 15:08:55,749 INFO: Microblog startup [in /home/shazib/microblog/app/__init__.py:49]
2020-10-12 15:13:58,373 INFO: Microblog startup [in /home/shazib/microblog/app/__init__.py:49]
2020-10-12 15:16:22,422 INFO: Microblog startup [in /home/shazib/microblog/app/__init__.py:49]
2020-10-12 16:16:16,300 INFO: Microblog startup [in /home/shazib/microblog/app/__init__.py:49]
2020-10-12 20:02:00,212 INFO: Microblog startup [in /home/shazib/microblog/app/__init__.py:49]
2020-10-12 22:27:14,866 INFO: Microblog startup [in /home/shazib/microblog/app/__init__.py:49]
2020-10-13 00:08:21,037 INFO: Microblog startup [in /home/shazib/microblog/app/__init__.py:49]
2020-10-13 00:15:04,748 INFO: Microblog startup [in /home/shazib/microblog/app/__init__.py:49]
2020-10-13 00:27:05,501 INFO: Microblog startup [in /home/shazib/microblog/app/__init__.py:49]
2020-10-13 02:36:53,633 INFO: Microblog startup [in /home/shazib/microblog/app/__init__.py:51]
2020-10-13 02:40:25,562 INFO: Microblog startup [in /home/shazib/microblog/app/__init__.py:51]
2020-10-13 02:41:06,239 INFO: Microblog startup [in /home/shazib/microblog/app/__init__.py:51]
2020-10-13 02:42:41,709 INFO: Microblog startup [in /home/shazib/microblog/app/__init__.py:51]
2020-10-13 02:43:19,383 INFO: Microblog startup [in /home/shazib/microblog/app/__init__.py:51]
2020-10-13 02:44:06,596 INFO: Microblog startup [in /home/shazib/microblog/app/__init__.py:51]
2020-10-15 20:30:52,793 INFO: Microblog startup [in /home/shazib/microblog/app/__init__.py:54]
2020-10-24 16:09:45,322 INFO: Microblog startup [in /home/shazib/microblog/app/__init__.py:54]
2020-10-24 16:11:17,350 INFO: Microblog startup [in /home/shazib/microblog/app/__init__.py:54]
2020-10-24 16:11:32,992 ERROR: Exception on / [GET] [in /home/shazib/microblog/venv/lib/python3.8/site-packages/flask/app.py:1891]
Traceback (most recent call last):
  File "/home/shazib/microblog/venv/lib/python3.8/site-packages/flask/app.py", line 2447, in wsgi_app
    response = self.full_dispatch_request()
  File "/home/shazib/microblog/venv/lib/python3.8/site-packages/flask/app.py", line 1952, in full_dispatch_request
    rv = self.handle_user_exception(e)
  File "/home/shazib/microblog/venv/lib/python3.8/site-packages/flask/app.py", line 1821, in handle_user_exception
    reraise(exc_type, exc_value, tb)
  File "/home/shazib/microblog/venv/lib/python3.8/site-packages/flask/_compat.py", line 39, in reraise
    raise value
  File "/home/shazib/microblog/venv/lib/python3.8/site-packages/flask/app.py", line 1948, in full_dispatch_request
    rv = self.preprocess_request()
  File "/home/shazib/microblog/venv/lib/python3.8/site-packages/flask/app.py", line 2242, in preprocess_request
    rv = func()
  File "/home/shazib/microblog/app/routes.py", line 16, in before_request
    g.locale = str(get_locale())
  File "/home/shazib/microblog/venv/lib/python3.8/site-packages/flask_babel/__init__.py", line 226, in get_locale
    rv = babel.locale_selector_func()
  File "/home/shazib/microblog/app/__init__.py", line 58, in get_locale
    return request.accept_language.best_match(app.config['LANGUAGES'])
  File "/home/shazib/microblog/venv/lib/python3.8/site-packages/werkzeug/local.py", line 347, in __getattr__
    return getattr(self._get_current_object(), name)
AttributeError: 'Request' object has no attribute 'accept_language'
